<?xml version="1.0"?>

<robot name="robot_learn" xmlns:xacro="http://ros.org/wiki/xacro">
  <link name="base_link">
  </link>

  <!--BODY CRAFT-->
  <link name="Body">
    <visual>
      <origin rpy="0 0 0" xyz="0 0 0"/>
      <geometry>
        <mesh filename="package://robot_learnbotics/meshes/Capa.stl"/>
      </geometry>
    </visual>

    <collision>
      <origin rpy="0 0 0" xyz="0 0 0"/>
      <geometry>
        <mesh filename="package://robot_learnbotics/meshes/Capa.stl"/>
      </geometry>
    </collision>

    <inertial>
      <origin rpy="0 0 0" xyz="0 0 0"/>
      <mass value="0.327"/>
      <inertia ixx="0.00063300" ixy="0.00005131" ixz="0.00000034" iyy="0.00120200" iyz="0" izz="0.00102900"/>
    </inertial>
  </link>

  <joint name="base_to_Body" type="fixed">
    <parent link="base_link"/>
    <child link="Body"/>
    <origin rpy="1.571 0 0" xyz="0 0 0" />
  </joint>

  <gazebo reference="Body">
    <material>Gazebo/Red</material>
  </gazebo>

  <!--LEFT WHEEL CRAFT-->
  <link name="Left_Wheel">
    <visual>
      <origin rpy="1.571 0 0" xyz="0 0 0"/>
      <geometry>
        <mesh filename="package://robot_learnbotics/meshes/Wheel.stl"/>
      </geometry>
    </visual>

    <collision>
      <origin rpy="1.571 0 0" xyz="0 0 0"/>
      <geometry>
        <mesh filename="package://robot_learnbotics/meshes/Wheel.stl"/>
      </geometry>
    </collision>

    <inertial>
      <origin rpy="1.571 0 0" xyz="0 0 0"/>
      <mass value="0.027"/>
      <inertia ixx="0.00001095" ixy="0" ixz="0" iyy="0.00001095" iyz="0" izz="0.00002138"/>
    </inertial>
  </link>

  <joint name="Body_to_Left_Wheel" type="continuous">
    <parent link="Body"/>
    <child link="Left_Wheel"/>
    <origin rpy="1.571 0 0" xyz="-0.057649 -0.034678 -0.059005" />
    <axis xyz="0 -1 0" />
  </joint>

   <transmission name="trans_Left_Wheel">
    <type>transmission_interface/SimpleTransmission</type>
    <joint name="Body_to_Left_Wheel">
      <hardwareInterface>hardware_interface/VelocityJointInterface</hardwareInterface>
    </joint>
    <actuator name="Left_Wheel_motor">
      <mechanicalReduction>1</mechanicalReduction>
    </actuator>
	</transmission>
  <gazebo reference="Left_Wheel">
    <material>Gazebo/Blue</material>
  </gazebo>


  <!--RIGHT WHEEL CRAFT-->
  <link name="Right_Wheel">
    <visual>
      <origin rpy="-1.571 0 0" xyz="0 0 0"/>
      <geometry>
        <mesh filename="package://robot_learnbotics/meshes/Wheel.stl"/>
      </geometry>
    </visual>

    <collision>
      <origin rpy="-1.571 0 0" xyz="0 0 0"/>
      <geometry>
        <mesh filename="package://robot_learnbotics/meshes/Wheel.stl"/>
      </geometry>
    </collision>

    <inertial>
      <origin rpy="-1.571 0 0" xyz="0 0 0"/>
      <mass value="0.027"/>
      <inertia ixx="0.00001095" ixy="0" ixz="0" iyy="0.00001095" iyz="0" izz="0.00002138"/>
    </inertial>
  </link>

  <joint name="Body_to_Right_Wheel" type="continuous">
    <parent link="Body"/>
    <child link="Right_Wheel"/>
    <origin rpy="1.571 0 0" xyz="-0.057649 -0.034678 0.059005" />
    <axis xyz="0 -1 0" />
  </joint>

    <transmission name="trans_Right_Wheel">
    <type>transmission_interface/SimpleTransmission</type>
    <joint name="Body_to_Right_Wheel">
      <hardwareInterface>hardware_interface/VelocityJointInterface</hardwareInterface>
    </joint>
    <actuator name="Right_Wheel_motor">
      <mechanicalReduction>1</mechanicalReduction>
    </actuator>
	</transmission>

   <gazebo reference="Right_Wheel">
    <material>Gazebo/Blue</material>
  </gazebo>


  <!--SPHERE CRAFT-->
  <link name="Sphere">
    <visual>
      <origin rpy="0 0 0" xyz="0 0 0"/>
      <geometry>
        <mesh filename="package://robot_learnbotics/meshes/Sphere.stl"/>
      </geometry>
    </visual>

    <collision>
      <origin rpy="0 0 0" xyz="0 0 0"/>
      <geometry>
        <mesh filename="package://robot_learnbotics/meshes/Sphere.stl"/>
      </geometry>
    </collision>

    <inertial>
      <origin rpy="0 0 0" xyz="0 0 0"/>
      <mass value="0.01"/>
      <inertia ixx="0.00000042" ixy="0" ixz="0" iyy="0.00000042" iyz="0" izz="0.00000042"/>
    </inertial>
  </link>

  <joint name="Body_to_Sphere" type="continuous">
    <parent link="Body"/>
    <child link="Sphere"/>
    <origin rpy="0 0 0" xyz="0.028278 -0.064603 0.000136" />
    <axis xyz="0 0 -1" />
  </joint>

  <gazebo reference="Sphere">
    <material>Gazebo/Blue</material>
  </gazebo>

  <link name="Sphere_2">
    <visual>
      <origin rpy="0 0 0" xyz="0 0 0"/>
      <geometry>
        <mesh filename="package://robot_learnbotics/meshes/Sphere.stl"/>
      </geometry>
    </visual>

    <collision>
      <origin rpy="0 0 0" xyz="0 0 0"/>
      <geometry>
        <mesh filename="package://robot_learnbotics/meshes/Sphere.stl"/>
      </geometry>
    </collision>

    <inertial>
      <origin rpy="0 0 0" xyz="0 0 0"/>
      <mass value="0.01"/>
      <inertia ixx="0.00000042" ixy="0" ixz="0" iyy="0.00000042" iyz="0" izz="0.00000042"/>
    </inertial>
  </link>

  <joint name="Sphere_to_Sphere_2" type="continuous">
    <parent link="Sphere"/>
    <child link="Sphere_2"/>
    <origin rpy="0 0 0" xyz="0 0 0" />
    <axis xyz="0 -1 0" />
  </joint>

  <gazebo reference="Sphere_2">
    <material>Gazebo/Blue</material>
  </gazebo>

  <link name="Sphere_3">
    <visual>
      <origin rpy="0 0 0" xyz="0 0 0"/>
      <geometry>
        <mesh filename="package://robot_learnbotics/meshes/Sphere.stl"/>
      </geometry>
    </visual>

    <collision>
      <origin rpy="0 0 0" xyz="0 0 0"/>
      <geometry>
        <mesh filename="package://robot_learnbotics/meshes/Sphere.stl"/>
      </geometry>
    </collision>

    <inertial>
      <origin rpy="0 0 0" xyz="0 0 0"/>
      <mass value="0.01"/>
      <inertia ixx="0.00000042" ixy="0" ixz="0" iyy="0.00000042" iyz="0" izz="0.00000042"/>
    </inertial>
  </link>

  <joint name="Sphere_2_to_Sphere_3" type="continuous">
    <parent link="Sphere_2"/>
    <child link="Sphere_3"/>
    <origin rpy="0 0 0" xyz="0 0 0" />
    <axis xyz="-1 0 0" />
  </joint>

  <gazebo reference="Sphere_3">
    <material>Gazebo/Blue</material>
  </gazebo>

    
  <!--LIDAR CRAFT-->
  <link name="Lidar">

    <visual>
      <origin rpy="0 0 0" xyz="0 0 0"/>
      <geometry>
        <mesh filename="package://robot_learnbotics/meshes/vlp16.stl"/>
      </geometry>
    </visual>

    <collision>
      <origin rpy="0 0 0" xyz="0 0 0"/>
      <geometry>
        <mesh filename="package://robot_learnbotics/meshes/vlp16.stl"/>
      </geometry>
    </collision>

    <inertial>
      <origin rpy="0 0 0" xyz="0 0 0"/>
      <mass value ="0.05"/>
      <inertia ixx="0.000909131" iyy="0.000909131" izz="0.001107105" ixy="0" ixz="0" iyz="0"/>
    </inertial>
  </link>

  <joint name="Body_to_Lidar" type="fixed">
    <parent link="Body"/>
    <child link="Lidar"/>
    <origin rpy="-1.571 1.571 0" xyz="0 0.07911977 0"/>
  </joint>

  
  <!-- RAY SENSOR CRAFT -->
  <gazebo reference="Lidar">
    <sensor type="ray" name="head_hokuyo_sensor">
      <pose>0 0 0 0 0 0</pose>
      <visualize>true</visualize>
      <update_rate>30</update_rate>
      <ray>
        <scan>
          <horizontal>
            <samples>720</samples>
            <resolution>1</resolution>
            <min_angle>-${3.1415926535897931}</min_angle>
            <max_angle>${3.1415926535897931}</max_angle>
          </horizontal>
          <vertical>
            <samples>16</samples>
            <resolution>1</resolution>
            <min_angle>-${15.0*3.1415926535897931/180.0}</min_angle>
            <max_angle>${15.0*3.1415926535897931/180.0}</max_angle>
          </vertical>
        </scan>
        <range>
          <min>0.2</min>
          <max>7</max>
          <resolution>0.02</resolution>
        </range>
        <noise>
          <type>gaussian</type>
          <mean>0.0</mean>
          <stddev>0.02</stddev>
        </noise>
      </ray>
      <material>Gazebo/White</material>
      <plugin name="gazebo_ros_head_hokuyo_sensor" filename="package://robot_learnbotics/plugin/libgazebo_ros_velodyne_laser.so">
        <topicName>/robot_learnbotics/laser/scan</topicName>
        <frameName>Lidar</frameName>
      </plugin>
    </sensor>
  </gazebo>


  <!--CAMERA CRAFT-->
  <link name="Camera">

    <visual>
      <origin rpy="0 0 0" xyz="0 0 0"/>
      <geometry>
        <mesh filename="package://robot_learnbotics/meshes/Camera.stl"/>
      </geometry>
    </visual>

    <collision>
      <origin rpy="0 0 0" xyz="0 0 0"/>
      <geometry>
        <mesh filename="package://robot_learnbotics/meshes/Camera.stl"/>
      </geometry>
    </collision>

    <inertial>
      <origin rpy="0 0 0" xyz="0 0 0"/>
      <mass value="0.002"/>
      <inertia ixx="1.397e-7" ixy="0" ixz="-2.070e-12" iyy="1.512e-7" iyz="1.844e-9" izz="7.943e-8"/>
    </inertial>
  </link>

  <joint name="Body_to_Camera" type="fixed">
    <parent link="Body"/>
    <child link="Camera"/>
    <origin rpy="-1.571 0 0" xyz="0.07456502 0.02996464 0.00016464"/>
  </joint>

   
  <!--CAMERA SENSOR-->
  <gazebo reference="Camera">
    <sensor type="camera" name="camera_top">
      <update_rate>30.0</update_rate>
      <camera name="head">
        <horizontal_fov>1.3962634</horizontal_fov>
        <image>
          <width>1366</width>
          <height>768</height>
          <format>R8G8B8</format>
        </image>
        <clip>
          <near>0.02</near>
          <far>300</far>
        </clip>
      </camera>
      <plugin name="camera_controller" filename="libgazebo_ros_camera.so">
        <alwaysOn>true</alwaysOn>
        <updateRate>0.0</updateRate>
        <cameraName>diff/camera_top</cameraName>
        <imageTopicName>image_raw</imageTopicName>
        <cameraInfoTopicName>camera_info</cameraInfoTopicName>
        <frameName>Camera</frameName>
        <hackBaseline>0.07</hackBaseline>
        <distortionK1>0.0</distortionK1>
        <distortionK2>0.0</distortionK2>
        <distortionK3>0.0</distortionK3>
        <distortionT1>0.0</distortionT1>
        <distortionT2>0.0</distortionT2>
      </plugin>
      <material>Gazebo/White</material>
    </sensor>
  </gazebo>

  <gazebo>
    <plugin name="gazebo_ros_control" filename="libgazebo_ros_diff_drive.so">
      <robotNamespace>/</robotNamespace>
      <legacyModeNS>true</legacyModeNS>
      <alwaysOn>true</alwaysOn>
      <legacyMode>false</legacyMode>
      <updateRate>40</updateRate>
      <leftJoint>Body_to_Left_Wheel</leftJoint>
      <rightJoint>Body_to_Right_Wheel</rightJoint>
      <wheelSeparation>0.10966201</wheelSeparation>
      <wheelDiameter>0.075</wheelDiameter>
      <torque>20</torque>
      <commandTopic>cmd_vel</commandTopic>
      <odometryTopic>odom</odometryTopic>
      <odometryFrame>odom</odometryFrame>
      <publishWheelTF>true</publishWheelTF>
      <publishOdomTF>true</publishOdomTF>
      <publishWheelJointState>true</publishWheelJointState>
      <robotBaseFrame>base_link</robotBaseFrame>
    </plugin>
  </gazebo>


</robot>







